<?xml version="1.0"?>
<robot name="luko">

  <link name="base_link">
    <visual>
      <geometry>
        <box size="0.4 0.2 0.02"/>
      </geometry>
    </visual>
  </link>

  <link name="cylinder">
    <visual>
      <geometry>
        <cylinder radius="0.035" length="0.07"/>
      </geometry>
      <origin rpy="0 0 0" xyz="0 0 0.045"/>
    </visual>
  </link>

  <joint name="base_joint" type="fixed">
    <parent link="base_link"/>
    <child link="cylinder"/>
    <origin xyz="0 0 0"/>
  </joint>

  <link name="lower_link">
    <visual>
      <origin xyz="0 0 0.1" rpy="1.57 0 0" />
      <geometry>
        <box size="0.01 0.05 0.05" />
      </geometry>
      <material name="blue">
        <color rgba="0 0 .8 1" />
      </material>
    </visual>
  </link>

  <joint name="cylinder_joint" type="fixed">
    <parent link="cylinder"/>
    <child link="lower_link"/>
    <origin xyz="0 0 0"/>
  </joint>

	
  <joint name="joint0" type="revolute">
    <parent link="lower_link"/>
    <child link="link1"/>
    <origin xyz="0 0 0" rpy="0 0 0" />
    <axis xyz="1 0 0" />
    <limit lower="-1.57" upper="1.57" effort="0.5293" velocity="6.159937255" />
  </joint>

  <link name="link1">
    <visual>
      <origin xyz="0 -0.02 0.250" rpy="0 0 0" />
      <geometry>
        <cylinder radius="0.005" length="0.25" />
      </geometry>
      <material name="yellow">
        <color rgba=".8 0 .8 1" />
      </material>
    </visual>
  </link>

  <joint name="joint1" type="revolute">
    <parent link="base_link"/>
    <child link="link2"/>
    <origin xyz="0 0.5 0" rpy="0 0 0" />
    <axis xyz="1 0 0" />
    <limit lower="-1.57" upper="1.57" effort="0.5293" velocity="6.159937255" />
    <mimic joint="joint0" multiplier="1" offset="0" />
  </joint>

  <link name="link2">
    <visual>
      <origin xyz="0 0.02 0.0250" rpy="0 0 0" />
      <geometry>
        <cylinder radius="0.005" length="0.25" />
      </geometry>
      <material name="green">
        <color rgba="0 .8 0 1" />
      </material>
    </visual>
  </link>

  <joint name="joint2" type="revolute">
    <parent link="link1"/>
    <child link="link3"/>
    <origin xyz="0 0 0.5" rpy="0 0 0" />
    <axis xyz="1 0 0" />
    <limit lower="-1.57" upper="1.57" effort="0.5293" velocity="6.159937255" />
    <mimic joint="joint0" multiplier="-1" offset="0" />
  </joint>

  <link name="link3">
    <visual>
      <origin xyz="0 0.25 0" rpy="1.57 0 0" />
      <geometry>
        <cylinder radius="0.02" length="0.05" />
      </geometry>
      <material name="red">
        <color rgba=".8 0 0 1" />
      </material>
    </visual>
  </link>

</robot>


