<?xml version="1.0"?>
<robot name="luko">

<!-- Bottom base, the piece of metal from an old screen -->
  <link name="base_link">
    <visual>
      <geometry>
        <box size="0.4 0.2 0.02"/>
      </geometry>
    </visual>
  </link>

<!-- The cylindrical-shaped rotating joint between the base and the arm mount -->
  <link name="cylinder">
    <visual>
      <geometry>
        <cylinder radius="0.035" length="0.07"/>
      </geometry>
      <origin rpy="0 0 0" xyz="0 0 0.045"/>
    </visual>
  </link>

  <joint name="base_joint" type="fixed">
    <parent link="base_link"/>
    <child link="cylinder"/>
    <origin xyz="0 0 0"/>
  </joint>

<!-- Arm mount inside the cylindrical thingy -->
  <joint name="cylinder_joint" type="revolute">
    <parent link="cylinder"/>
    <child link="bottom_mount"/>
    <origin xyz="0 0 0"/>
    <axis xyz="0 0 1" />
    <limit lower="-3.14" upper="3.14" effort="0.5293" velocity="6.159937255" />
 </joint>

<!-- Bottom arm mount -->
  <link name="bottom_mount">
    <visual>
      <origin xyz="0 0 0.1" rpy="1.57 0 0" />
      <geometry>
        <box size="0.01 0.05 0.05" />
      </geometry>
      <material name="blue">
        <color rgba="0 0 .8 1" />
      </material>
    </visual>
  </link>

<!-- Lower arm fwd rod -->
  <link name="low_fwd_rod">
    <visual>
      <origin xyz="0 0 0.11" rpy="0 0 0" />
      <geometry>
        <cylinder radius="0.005" length="0.22" />
      </geometry>
      <material name="yellow">
        <color rgba=".8 0 .8 1" />
      </material>
    </visual>
  </link>

<!-- Lower arm aft rod -->
  <link name="low_aft_rod">
    <visual>
      <origin xyz="0 0 0.11" rpy="0 0 0" />
      <geometry>
        <cylinder radius="0.005" length="0.22" />
      </geometry>
      <material name="green">
        <color rgba="0 .8 0 1" />
      </material>
    </visual>
  </link>

<!-- Bottom mount to fwd lower rod -->
  <joint name="low_joint0" type="revolute">
    <parent link="bottom_mount"/>
    <child link="low_fwd_rod"/>
    <origin xyz="0 -0.0145 0.085" rpy="-0.38 0 0" />
    <axis xyz="1 0 0" />
    <limit lower="-1.57" upper="1.57" effort="0.5293" velocity="6.159937255" />
  </joint>

<!-- Bottom mount to aft lower rod -->
  <joint name="low_joint1" type="revolute">
    <parent link="bottom_mount"/>
    <child link="low_aft_rod"/>
    <origin xyz="0 0.0145 0.100" rpy="-0.30 0 0" />
    <axis xyz="1 0 0" />
    <limit lower="-1.57" upper="1.57" effort="0.5293" velocity="6.159937255" />
    <mimic joint="low_joint0" multiplier="1" offset="0" />
  </joint>

<!-- Fwd lower rod to middle piece -->
  <joint name="low_joint2" type="revolute">
    <parent link="low_fwd_rod"/>
    <child link="middle_piece"/>
    <origin xyz="0 0 0.22" rpy="0 0 0" />
    <axis xyz="1 0 0" />
    <limit lower="-1.57" upper="1.57" effort="0.5293" velocity="6.159937255" />
    <mimic joint="low_joint0" multiplier="-1" offset="0" />
  </joint>

<!-- The piece of plastic joining the lower and upper arms -->
  <link name="middle_piece">
    <visual>
      <origin xyz="0 -0.015 0.020" rpy="0.38 0 0" />
      <geometry>
        <box size="0.01 0.05 0.05" />
      </geometry>
      <material name="red">
        <color rgba=".8 0 0 1" />
      </material>
    </visual>
  </link>

<!-- Upper arm rods 1 and 2 -->
  <link name="up_fwd_rod">
    <visual>
      <origin xyz="0 -0.085 0" rpy="1.57 0 0" />
      <geometry>
        <cylinder radius="0.005" length="0.17" />
      </geometry>
      <material name="yellow">
        <color rgba=".8 0 .8 1" />
      </material>
    </visual>
  </link>

  <link name="up_aft_rod">
    <visual>
      <origin xyz="0 -0.085 0" rpy="1.57 0 0" />
      <geometry>
        <cylinder radius="0.005" length="0.17" />
      </geometry>
      <material name="green">
        <color rgba="0 .8 0 1" />
      </material>
    </visual>
  </link>

<!-- Piece of plastic between upper arm and head -->
  <link name="head_mount">
    <visual>
      <origin xyz="0 -0.015 0.015" rpy="1.57 0 0" />
      <geometry>
        <box size="0.01 0.03 0.03" />
      </geometry>
      <material name="red">
        <color rgba=".8 0 0 1" />
      </material>
    </visual>
  </link>

<!-- Middle piece to fwd upper rod -->
  <joint name="up_joint0" type="revolute">
    <parent link="middle_piece"/>
    <child link="up_fwd_rod"/>
    <origin xyz="0 -0.01 0" rpy="0.38 0 0" />
    <axis xyz="1 0 0" />
    <limit lower="-1.57" upper="1.57" effort="0.5293" velocity="6.159937255" />
  </joint>

<!-- Middle piece to aft upper rod -->
  <joint name="up_joint1" type="revolute">
    <parent link="middle_piece"/>
    <child link="up_aft_rod"/>
    <origin xyz="0 -0.025 0.01" rpy="0.38 0 0" />
    <axis xyz="1 0 0" />
    <limit lower="-1.57" upper="1.57" effort="0.5293" velocity="6.159937255" />
    <mimic joint="up_joint0" multiplier="1" offset="0" />
  </joint>

<!-- Fwd upper rod to head mount -->
  <joint name="up_joint2" type="revolute">
    <parent link="up_fwd_rod"/>
    <child link="head_mount"/>
    <origin xyz="0 -0.165 -0.005" rpy="0 0 0" />
    <axis xyz="1 0 0" />
    <limit lower="-1.57" upper="1.57" effort="0.5293" velocity="6.159937255" />
    <mimic joint="up_joint0" multiplier="-1" offset="0" />
  </joint>

<!-- Head mount link -->
  <link name="head_link">
    <visual>
      <origin xyz="0 -0.01 0" rpy="1.57 0 0" />
      <geometry>
        <cylinder radius="0.004" length="0.02" />
      </geometry>
      <material name="green">
        <color rgba="0 .8 0 1" />
      </material>
    </visual>
  </link>

  <joint name="head_bearing_link" type="revolute">
    <parent link="head_mount"/>
    <child link="head_link"/>
    <origin xyz="0 -0.02 0.005" rpy="0 0 0" />
    <axis xyz="1 0 0" />
    <limit lower="-1.57" upper="1.57" effort="0.5293" velocity="6.159937255" />
  </joint>

  <link name="head_aft">
    <visual>
      <origin xyz="0 -0.04 -0.01" rpy="0 0 0" />
      <geometry>
        <cylinder radius="0.025" length="0.07" />
      </geometry>
      <material name="green">
        <color rgba="0 .8 0 1" />
      </material>
    </visual>
  </link>

  <joint name="head_to_lamp" type="fixed">
    <parent link="head_link"/>
    <child link="head_aft"/>
    <origin xyz="0 0 0" rpy="0 0 0" />
  </joint>

  <link name="head_fwd">
    <visual>
      <origin xyz="0 -0.040 -0.06" rpy="0 0 0" />
      <geometry>
        <cylinder radius="0.05" length="0.05" />
      </geometry>
      <material name="green">
        <color rgba="0 .8 0 1" />
      </material>
    </visual>
  </link>

  <joint name="head_to_reflector" type="fixed">
    <parent link="head_aft"/>
    <child link="head_fwd"/>
    <origin xyz="0 0 0" rpy="0 0 0" />
  </joint>


</robot>

